[2023-03-02T21:23:50.132+0000] {taskinstance.py:1083} INFO - Dependencies all met for <TaskInstance: convert_csv_in_excel.main manual__2023-03-02T21:23:48.108945+00:00 [queued]>
[2023-03-02T21:23:50.143+0000] {taskinstance.py:1083} INFO - Dependencies all met for <TaskInstance: convert_csv_in_excel.main manual__2023-03-02T21:23:48.108945+00:00 [queued]>
[2023-03-02T21:23:50.143+0000] {taskinstance.py:1279} INFO - 
--------------------------------------------------------------------------------
[2023-03-02T21:23:50.144+0000] {taskinstance.py:1280} INFO - Starting attempt 1 of 1
[2023-03-02T21:23:50.144+0000] {taskinstance.py:1281} INFO - 
--------------------------------------------------------------------------------
[2023-03-02T21:23:50.165+0000] {taskinstance.py:1300} INFO - Executing <Task(PythonOperator): main> on 2023-03-02 21:23:48.108945+00:00
[2023-03-02T21:23:50.171+0000] {standard_task_runner.py:55} INFO - Started process 1312 to run task
[2023-03-02T21:23:50.175+0000] {standard_task_runner.py:82} INFO - Running: ['***', 'tasks', 'run', 'convert_csv_in_excel', 'main', 'manual__2023-03-02T21:23:48.108945+00:00', '--job-id', '126', '--raw', '--subdir', 'DAGS_FOLDER/convert_csv_in_excel.py', '--cfg-path', '/tmp/tmpxiu5_aqp']
[2023-03-02T21:23:50.176+0000] {standard_task_runner.py:83} INFO - Job 126: Subtask main
[2023-03-02T21:23:50.274+0000] {task_command.py:388} INFO - Running <TaskInstance: convert_csv_in_excel.main manual__2023-03-02T21:23:48.108945+00:00 [running]> on host d28bc369eb67
[2023-03-02T21:23:50.385+0000] {taskinstance.py:1509} INFO - Exporting the following env vars:
AIRFLOW_CTX_DAG_OWNER=***
AIRFLOW_CTX_DAG_ID=convert_csv_in_excel
AIRFLOW_CTX_TASK_ID=main
AIRFLOW_CTX_EXECUTION_DATE=2023-03-02T21:23:48.108945+00:00
AIRFLOW_CTX_TRY_NUMBER=1
AIRFLOW_CTX_DAG_RUN_ID=manual__2023-03-02T21:23:48.108945+00:00
[2023-03-02T21:23:50.390+0000] {taskinstance.py:1768} ERROR - Task failed with exception
Traceback (most recent call last):
  File "/home/airflow/.local/lib/python3.7/site-packages/airflow/operators/python.py", line 175, in execute
    return_value = self.execute_callable()
  File "/home/airflow/.local/lib/python3.7/site-packages/airflow/operators/python.py", line 192, in execute_callable
    return self.python_callable(*self.op_args, **self.op_kwargs)
  File "/opt/airflow/dags/convert_csv_in_excel.py", line 11, in transfrom
    df = pd.read_csv('..\\data\\operations.csv')
  File "/home/airflow/.local/lib/python3.7/site-packages/pandas/util/_decorators.py", line 311, in wrapper
    return func(*args, **kwargs)
  File "/home/airflow/.local/lib/python3.7/site-packages/pandas/io/parsers/readers.py", line 586, in read_csv
    return _read(filepath_or_buffer, kwds)
  File "/home/airflow/.local/lib/python3.7/site-packages/pandas/io/parsers/readers.py", line 482, in _read
    parser = TextFileReader(filepath_or_buffer, **kwds)
  File "/home/airflow/.local/lib/python3.7/site-packages/pandas/io/parsers/readers.py", line 811, in __init__
    self._engine = self._make_engine(self.engine)
  File "/home/airflow/.local/lib/python3.7/site-packages/pandas/io/parsers/readers.py", line 1040, in _make_engine
    return mapping[engine](self.f, **self.options)  # type: ignore[call-arg]
  File "/home/airflow/.local/lib/python3.7/site-packages/pandas/io/parsers/c_parser_wrapper.py", line 51, in __init__
    self._open_handles(src, kwds)
  File "/home/airflow/.local/lib/python3.7/site-packages/pandas/io/parsers/base_parser.py", line 229, in _open_handles
    errors=kwds.get("encoding_errors", "strict"),
  File "/home/airflow/.local/lib/python3.7/site-packages/pandas/io/common.py", line 707, in get_handle
    newline="",
FileNotFoundError: [Errno 2] No such file or directory: '..\\data\\operations.csv'
[2023-03-02T21:23:50.404+0000] {taskinstance.py:1323} INFO - Marking task as FAILED. dag_id=convert_csv_in_excel, task_id=main, execution_date=20230302T212348, start_date=20230302T212350, end_date=20230302T212350
[2023-03-02T21:23:50.421+0000] {standard_task_runner.py:105} ERROR - Failed to execute job 126 for task main ([Errno 2] No such file or directory: '..\\data\\operations.csv'; 1312)
[2023-03-02T21:23:50.468+0000] {local_task_job.py:208} INFO - Task exited with return code 1
[2023-03-02T21:23:50.519+0000] {taskinstance.py:2578} INFO - 0 downstream tasks scheduled from follow-on schedule check
